<?xml version="1.0"?>
<!-- 
  Robot model adapted from https://github.com/CIR-KIT/steer_drive_ros/blob/kinetic-devel/steer_drive_controller/test/common/urdf/wheel.xacro

  Modifications:
    <transmissions> elements have been updated and added to 'front_steer'.
    Update inertials.
    Remove dependency on externally defined parameters.
-->
<robot name="wheel" xmlns:xacro="http://wiki.ros.org/xacro">
  <!-- Include xacro for materials and inertials -->
  <xacro:include filename="$(find hakuroukun_description)/urdf/robot_part/materials.xacro"/>
  <xacro:include filename="$(find hakuroukun_description)/urdf/robot_part/inertials.xacro"/>

  <!-- Properties -->
  <xacro:property name="steer_effort" value="10.0"/>
  <xacro:property name="steer_velocity" value="5.0"/>
  <xacro:property name="steer_limit_deg" value="45.0"/>
  <xacro:property name="robot_namespace" value="hakuroukun"/>
  <xacro:property name="wheel_radius" value="0.125"/>
  <xacro:property name="b2f_axis_distance" value="1.1"/>
  <xacro:property name="b_axis_length" value="0.8"/>
  
  <!-- Bicycle model front steering link - FRONT REVOLUTE -->
  <xacro:macro name="front_steer"
    params="
      name
      parent
      steer_radius
      steer_thickness
      steer_mass
      base_length
      base_width
      axle_offset
      steer_height">
    <link name="${name}_steer_link">
      <visual>
        <origin xyz="0 0 0" rpy="0 0 0"/>
        <geometry>
          <cylinder radius="${steer_radius}" length="${steer_thickness}"/>
        </geometry>
        <material name="light_grey"/>
      </visual>
      <collision>
        <origin xyz="0 0 0" rpy="0 0 0"/>
        <geometry>
          <cylinder radius="${steer_radius}" length="${steer_thickness}"/>
        </geometry>
      </collision>
      <xacro:wheel_inertial 
          rpy="0 0 0" xyz="0 0 0"
          mass="${steer_mass}"
          radius="${steer_radius}" length="${steer_thickness}" />
    </link>

    <joint name="${name}_steer_joint" type="revolute">
      <parent link="${parent}_link"/>
      <child link="${name}_steer_link"/>
      <origin xyz="${b2f_axis_distance} 0 ${steer_height}" rpy="0 0 0"/>
      <axis xyz="0 0 1"/>
      <limit effort="${steer_effort}"
             lower="${-180.0 * deg_to_rad}" upper="${180.0 * deg_to_rad}"
             velocity="${steer_velocity}"/>
    </joint>

    <transmission name="${name}_steer_joint_trans">
      <type>transmission_interface/SimpleTransmission</type>
      <actuator name="${name}_steer_joint_motor">
        <mechanicalReduction>1</mechanicalReduction>
        <hardwareInterface>hardware_interface/PositionJointInterface</hardwareInterface>
      </actuator>
      <joint name="${name}_steer_joint">
        <hardwareInterface>hardware_interface/PositionJointInterface</hardwareInterface>
      </joint>
    </transmission>

  </xacro:macro>

<!--========================================================================================-->
  <!-- Bicycle model front wheel link (passive - no transmission) -->
  <xacro:macro name="front_wheel"
    params="
      name
      parent
      wheel_radius
      wheel_thickness
      wheel_mass
      *origin">
    <link name="${name}_wheel_link">
      <visual>
        <origin xyz="0 0 0" rpy="0 0 0"/>
        <geometry>
          <mesh filename="package://hakuroukun_description/meshes/hakuroukun_front_wheel.stl" scale="0.001 0.001 0.001" />
        </geometry>
        <material name="light_grey"/>
      </visual>
      <collision>
        <origin xyz="0 0 0" rpy="0 0 0"/>
        <geometry>
          <mesh filename="package://hakuroukun_description/meshes/hakuroukun_front_wheel.stl" scale="0.001 0.001 0.001" />
        </geometry>
      </collision>
      <xacro:wheel_inertial 
          rpy="0 0 0" xyz="0 0 0"
          mass="${wheel_mass}"
          radius="${wheel_radius}" length="${wheel_thickness}" />
    </link>

    <joint name="${name}_wheel_joint" type="continuous">
      <parent link="${parent}_link"/>
      <child link="${name}_wheel_link"/>
      <xacro:insert_block name="origin"/>
      <axis xyz="0 1 0"/>
    </joint>

    <!-- <transmission name="${name}_steer_joint_trans">
      <type>transmission_interface/SimpleTransmission</type>
      <actuator name="${name}_steer_joint_motor">
        <mechanicalReduction>1</mechanicalReduction>
        <hardwareInterface>hardware_interface/PositionJointInterface</hardwareInterface>
      </actuator>
      <joint name="${name}_wheel_joint">
        <hardwareInterface>hardware_interface/PositionJointInterface</hardwareInterface>
      </joint>
    </transmission> -->

    <gazebo reference="${name}_wheel_link">
      <material>Gazebo/Grey</material>
    </gazebo>

    <gazebo reference="${name}_wheel_joint">
      <provideFeedback>true</provideFeedback>
    </gazebo>
  </xacro:macro>

<!--========================================================================================-->

  <!-- Bicycle model rear wheel link (required for steer_drive_controller) -->
  <xacro:macro name="rear_wheel"
    params="
      name
      parent
      wheel_radius
      wheel_thickness
      wheel_mass
      *origin">
    <link name="${name}_wheel_link">
      <visual>
        <origin xyz="0 0 0" rpy="0 0 0"/>
        <geometry>
          <mesh filename="package://hakuroukun_description/meshes/hakuroukun_back_wheel.stl" scale="0.001 0.001 0.001" />
        </geometry>
        <material name="light_grey"/>
      </visual>
      <collision>
        <origin xyz="0 0 0" rpy="0 0 0"/>
        <geometry>
          <mesh filename="package://hakuroukun_description/meshes/hakuroukun_back_wheel.stl" scale="0.001 0.001 0.001" />
        </geometry>
      </collision>
      <xacro:wheel_inertial 
          rpy="0 0 0" xyz="0 0 0"
          mass="${wheel_mass}"
          radius="${wheel_radius}" length="${wheel_thickness}" />
    </link>

    <joint name="${name}_wheel_joint" type="continuous">
      <parent link="${parent}_link"/>
      <child link="${name}_wheel_link"/>
      <xacro:insert_block name="origin"/>
      <axis xyz="0 1 0"/>
    </joint>

    <transmission name="${name}_wheel_joint_trans">
      <type>transmission_interface/SimpleTransmission</type>
      <actuator name="${name}_wheel_joint_motor">
        <mechanicalReduction>1</mechanicalReduction>
        <hardwareInterface>hardware_interface/VelocityJointInterface</hardwareInterface>
      </actuator>
      <joint name="${name}_wheel_joint">
        <hardwareInterface>hardware_interface/VelocityJointInterface</hardwareInterface>
      </joint>
    </transmission>

    <gazebo reference="${name}_wheel_link">
      <material>Gazebo/Grey</material>
    </gazebo>
  </xacro:macro>

<!-- REAR Left / Right -->
<xacro:macro name="rear_wheel_lr"
    params="
      name
      parent
      wheel_radius
      wheel_thickness
      wheel_mass
      *origin">
    <link name="${name}_wheel_link">
      <visual>
        <origin xyz="0 0 0" rpy="0 0 0"/>
        <geometry>
          <mesh filename="package://hakuroukun_description/meshes/hakuroukun_back_wheel.stl" scale="0.001 0.001 0.001" />
        </geometry>
        <material name="light_grey"/>
      </visual>
      <collision>
        <origin xyz="0 0 0" rpy="0 0 0"/>
        <geometry>
          <mesh filename="package://hakuroukun_description/meshes/hakuroukun_back_wheel.stl" scale="0.001 0.001 0.001" />
        </geometry>
      </collision>
      <xacro:wheel_inertial 
          rpy="0 0 0" xyz="0 0 0"
          mass="${wheel_mass}"
          radius="${wheel_radius}" length="${wheel_thickness}" />
    </link>

    <joint name="${name}_wheel_joint" type="continuous">
      <parent link="${parent}_link"/>
      <child link="${name}_wheel_link"/>
      <xacro:insert_block name="origin"/>
      <axis xyz="0 1 0"/>
    </joint>

    <transmission name="${name}_wheel_joint_trans">
      <type>transmission_interface/SimpleTransmission</type>
      <actuator name="${name}_wheel_joint_motor">
        <mechanicalReduction>1</mechanicalReduction>
        <hardwareInterface>hardware_interface/VelocityJointInterface</hardwareInterface>
      </actuator>
      <joint name="${name}_wheel_joint">
        <hardwareInterface>hardware_interface/VelocityJointInterface</hardwareInterface>
      </joint>
    </transmission>

    <gazebo reference="${name}_wheel_link">
      <material>Gazebo/Grey</material>
    </gazebo>
  </xacro:macro>


</robot>
